Workbook

Sheet Summary
A1: External Literature Validation — Coverage Dashboard
A4: KPI | B4: Value | C4: Meaning | D4: Use
A5: Master structures | B5: =COUNTA(Master_Literature!B5:B118) | C5: Input-ready structures / variants | D5: Broad stress test
A6: RDKit PASS | B6: =COUNTIF(Master_Literature!F5:F118,"PASS") | C6: Repeat SMILES parsed by RDKit in build environment | D6: Input sanity
A7: Tier A | B7: =COUNTIF(Master_Literature!U5:U118,"A") | C7: Tg + density + Tc available | D7: Strongest direct quantitative panel
A8: Tier B | B8: =COUNTIF(Master_Literature!U5:U118,"B") | C8: 2/3 core properties available | D8: Useful partial validation
A9: Tier C | B9: =COUNTIF(Master_Literature!U5:U118,"C") | C9: Mostly Tg only | D9: Trend / OOD stress test
A10: Tire/high relevance | B10: =COUNTIF(Master_Literature!G5:G118,"High") | C10: Tire-linked homopolymer/proxy structures | D10: Prioritize
A11: Conditioned FFV/Rg/PALS records | B11: =COUNTA(FFV_Rg_Conditioned!B5:B36) | C11: Definition/condition tagged measurements | D11: Mechanistic / matched-condition validation
A12: Industrial copolymer rows | B12: =COUNTA(Industrial_Copolymers!B5:B13) | C12: SBR/NBR/HNBR/EPDM/IIR etc. | D12: Composition-aware external check
A14: Validation Tier | B14: Definition | C14: Recommended action | D14: Caveat
A15: A | B15: Tg + density + Tc | C15: Run first and compute absolute error / range hit | D15: Still condition/grade sensitive
A16: B | B16: Two of Tg/density/Tc | C16: Use for partial external validation | D16: Do not score missing properties as failures
A17: C | B17: Mostly Tg | C17: Use as large trend/OOD stress test | D17: Not a complete multi-property benchmark
A19: Top-priority tire validation logic
A20: PB/BR and PI/NR are the cleanest tire-linked homopolymer checks. SBR, NBR, HNBR, EPDM and IIR are composition-sensitive copolymers/terpolymers, so a single repeat-unit SMILES cannot fully represent the material. Use the Industrial_Copolymers sheet to avoid overclaiming. For FFV and especially Rg, only compare after matching definition, molecular weight/chain length, temperature and state; otherwise treat literature values as qualitative/conditional evidence.

Sheet README
A1: External Literature Validation Pack — Polymer Tg / Density / FFV / Thermal Conductivity / Rg
A4: Purpose
A5: This workbook is a large external-literature validation pack for a polymer-property AI tool. It intentionally separates directly comparable bulk properties (Tg, density, thermal conductivity) from condition-dependent FFV/PALS/Rg measurements. Blank cells mean no sufficiently defensible value was entered from the curated sources used here; they are NOT zeros.
A9: Key rule | B9: Meaning
A10: Tc | B10: Thermal conductivity, W m^-1 K^-1 (NOT crystallization temperature).
A11: Tg | B11: Highly dependent on molecular weight, tacticity, thermal history, moisture, crystallinity and measurement protocol.
A12: Density | B12: Depends on crystallinity, grade, additives, temperature and morphology.
A13: FFV | B13: Definition-sensitive. 'Fractional excess free volume at Tg' and PALS hole sizes are NOT automatically the same target as a geometric MD FFV.
A14: Rg | B14: Strongly depends on molecular weight/chain length, solvent or melt state, concentration and temperature.
A15: Repeat SMILES | B15: Many are input-ready homopolymer repeat units with * connection points. Copolymers/terpolymers often have no unique single repeat SMILES.
A16: Validation strategy | B16: Use Tg/Density/Tc for quantitative external error first; treat FFV/Rg only under matched definitions/conditions.
A18: Recommended use
A19: 1) Start with HighQuality_Panel. 2) Paste each Repeat_SMILES into the AI tool and enter predictions. 3) Compare prediction to literature primary value/range. 4) Use Master_Literature for broad stress testing. 5) Use FFV_Rg_Conditioned only when the AI target definition/chain length is matched. 6) For tire polymers, check PB/BR, PI/NR, PIB/IIR proxy, SBR/EPDM/NBR/HNBR in the dedicated sheets.
A26: Important: this is a curated validation aid, not a claim that every literature number is a universal material constant. Where sources disagree, the workbook keeps ranges/notes instead of hiding the disagreement.
A29: Generated | B29: 2026-08-15 13:55
A30: Master rows | B30: 114

Sheet Master_Literature
A1: Master Literature Library — input-ready repeat structures + curated experimental/reference properties
A4: ID | B4: Polymer | C4: Acronym | D4: Family | E4: Repeat_SMILES | F4: RDKit_Parse | G4: Tire_Relevance | H4: Tg_Primary_C | I4: Tg_Min_C | J4: Tg_Max_C | K4: Tg_Source_ID | L4: Density_Primary_g_cm3 | M4: Density_Min | N4: Density_Max | O4: Density_Source_ID | P4: Tc_Primary_W_mK | Q4: Tc_Min | R4: Tc_Max | S4: Tc_Source_ID | T4: Core_Property_Count | U4: Validation_Tier | V4: Notes
A5: 1 | B5: Acenaphthylene polymer | C5: PACN | D5: Aromatic vinyl | E5: *CC1c2ccccc2C1* | F5: PASS | H5: 214 | I5: 214 | J5: 214 | K5: MERCK_TG | T5: 1 | U5: C
A6: 2 | B6: N,N-Dimethylacrylamide | C6: PDMA | D6: Acrylamide | E6: *CC(C(=O)N(C)C)* | F6: PASS | H6: 89 | I6: 89 | J6: 89 | K6: MERCK_TG | T6: 1 | U6: C
A7: 3 | B7: Poly(4-acetoxystyrene) | C7: P4AcOS | D7: Styrenic | E7: *CC(c1ccc(OC(=O)C)cc1)* | F7: PASS | H7: 116 | I7: 116 | J7: 116 | K7: MERCK_TG | T7: 1 | U7: C
A8: 4 | B8: Poly(dimethylsiloxane) | C8: PDMS | D8: Siloxane | E8: *O[Si](C)(C)* | F8: PASS | H8: -127 | I8: -127 | J8: -127 | K8: MERCK_TG | T8: 1 | U8: C
A9: 5 | B9: Polyacrylamide | C9: PAM | D9: Acrylamide | E9: *CC(C(=O)N)* | F9: PASS | H9: 165 | I9: 165 | J9: 165 | K9: MERCK_TG | P9: 0.38 | Q9: 0.38 | R9: 0.38 | S9: TC_REVIEW | T9: 2 | U9: B
A10: 6 | B10: Poly(acrylic acid) | C10: PAA | D10: Acrylic | E10: *CC(C(=O)O)* | F10: PASS | H10: 105 | I10: 105 | J10: 105 | K10: MERCK_TG | P10: 0.37 | Q10: 0.37 | R10: 0.37 | S10: TC_REVIEW | T10: 2 | U10: B
A11: 7 | B11: Syndiotactic polyacrylonitrile | C11: s-PAN | D11: Nitrile vinyl | E11: *CC(C#N)* | F11: PASS | H11: 125 | I11: 125 | J11: 125 | K11: MERCK_TG | T11: 1 | U11: C
A12: 8 | B12: Poly(allyl glycidyl ether) | C12: PAGE | D12: Polyether | E12: *COCC1CO1* | F12: FAIL | H12: -78 | I12: -78 | J12: -78 | K12: MERCK_TG | T12: 1 | U12: C
A13: 9 | B13: Poly(benzyl acrylate) | C13: PBzA | D13: Acrylic | E13: *CC(C(=O)OCc1ccccc1)* | F13: PASS | H13: 6 | I13: 6 | J13: 6 | K13: MERCK_TG | T13: 1 | U13: C
A14: 10 | B14: Poly(benzyl methacrylate) | C14: PBzMA | D14: Methacrylic | E14: *CC(C)(C(=O)OCc1ccccc1)* | F14: PASS | H14: 54 | I14: 54 | J14: 54 | K14: MERCK_TG | T14: 1 | U14: C
A15: 11 | B15: Poly(dodecyl acrylate) | C15: PDA | D15: Acrylic | E15: *CC(C(=O)OCCCCCCCCCCCC)* | F15: PASS | H15: -3 | I15: -3 | J15: -3 | K15: MERCK_TG | T15: 1 | U15: C
A16: 12 | B16: Poly(dodecyl methacrylate) | C16: PDDMA | D16: Methacrylic | E16: *CC(C)(C(=O)OCCCCCCCCCCCC)* | F16: PASS | H16: -65 | I16: -65 | J16: -65 | K16: MERCK_TG | T16: 1 | U16: C
A17: 13 | B17: Bisphenol-A polycarbonate | C17: BPA-PC | D17: Polycarbonate | E17: *Oc1ccc(C(C)(C)c2ccc(OC(=O)O*)cc2)cc1 | F17: PASS | H17: 145 | I17: 145 | J17: 145 | K17: PLASTICS_BOOK | L17: 1.2 | M17: 1.2 | N17: 1.2 | O17: PLASTICS_BOOK | Q17: 0.18 | R17: 0.21 | S17: TC_ENG | T17: 3 | U17: A
A18: 14 | B18: Poly(4-bromostyrene) | C18: P4BrS | D18: Styrenic | E18: *CC(c1ccc(Br)cc1)* | F18: PASS | H18: 118 | I18: 118 | J18: 118 | K18: MERCK_TG | T18: 1 | U18: C
A19: 15 | B19: Poly(1-butene) | C19: PB-1 | D19: Polyolefin | E19: *CC(CC)* | F19: PASS | H19: -24 | I19: -24 | J19: -24 | K19: MERCK_TG | T19: 1 | U19: C
A20: 16 | B20: Poly(n-butyl acrylate) | C20: PnBA | D20: Acrylic | E20: *CC(C(=O)OCCCC)* | F20: PASS | G20: High | H20: -55.2 | I20: -55.2 | J20: -55.2 | K20: POLYACRYLATE | L20: 1.04 | M20: 1.04 | N20: 1.04 | O20: POLYACRYLATE | T20: 2 | U20: B
A21: 17 | B21: Poly(tert-butyl acrylate) | C21: PtBA | D21: Acrylic | E21: *CC(C(=O)OC(C)(C)C)* | F21: PASS | I21: 43 | J21: 107 | K21: MERCK_TG | T21: 1 | U21: C
A22: 18 | B22: Poly(n-butyl methacrylate) | C22: PnBMA | D22: Methacrylic | E22: *CC(C)(C(=O)OCCCC)* | F22: PASS | H22: 20 | I22: 20 | J22: 20 | K22: MERCK_TG | T22: 1 | U22: C
A23: 19 | B23: Poly(tert-butyl methacrylate) | C23: PtBMA | D23: Methacrylic | E23: *CC(C)(C(=O)OC(C)(C)C)* | F23: PASS | H23: 118 | I23: 118 | J23: 118 | K23: MERCK_TG | T23: 1 | U23: C
A24: 20 | B24: Poly(4-tert-butylstyrene) | C24: PtBS | D24: Styrenic | E24: *CC(c1ccc(C(C)(C)C)cc1)* | F24: PASS | H24: 127 | I24: 127 | J24: 127 | K24: MERCK_TG | T24: 1 | U24: C
A25: 21 | B25: Poly(butyl vinyl ether) | C25: PBVE | D25: Vinyl ether | E25: *CC(OCCCC)* | F25: PASS | H25: -55 | I25: -55 | J25: -55 | K25: MERCK_TG | T25: 1 | U25: C
A26: 22 | B26: Poly(caprolactone) | C26: PCL | D26: Polyester | E26: *OCCCCCC(=O)* | F26: PASS | H26: -60 | I26: -60 | J26: -60 | K26: MERCK_TG | T26: 1 | U26: C
A27: 23 | B27: Poly(chloroprene), cis-rich reference | C27: CR-cis | D27: Diene rubber | E27: *CC(Cl)=CC* | F27: PASS | G27: High | H27: -20 | I27: -20 | J27: -20 | K27: MERCK_TG | T27: 1 | U27: C
A28: 24 | B28: Poly(chloroprene), trans-rich reference | C28: CR-trans | D28: Diene rubber | E28: *CC(Cl)=CC* | F28: PASS | G28: High | H28: -40 | I28: -40 | J28: -40 | K28: MERCK_TG | T28: 1 | U28: C
A29: 25 | B29: Poly(2-chlorostyrene) | C29: P2ClS | D29: Styrenic | E29: *CC(c1ccccc1Cl)* | F29: PASS | H29: 119 | I29: 119 | J29: 119 | K29: MERCK_TG | T29: 1 | U29: C
A30: 26 | B30: Poly(3-chlorostyrene) | C30: P3ClS | D30: Styrenic | E30: *CC(c1cccc(Cl)c1)* | F30: PASS | H30: 90 | I30: 90 | J30: 90 | K30: MERCK_TG | T30: 1 | U30: C
A31: 27 | B31: Poly(4-chlorostyrene) | C31: P4ClS | D31: Styrenic | E31: *CC(c1ccc(Cl)cc1)* | F31: PASS | H31: 110 | I31: 110 | J31: 110 | K31: MERCK_TG | T31: 1 | U31: C
A32: 28 | B32: Poly(chlorotrifluoroethylene) | C32: PCTFE | D32: Fluoropolymer | E32: *C(F)(F)C(F)(Cl)* | F32: PASS | H32: 52 | I32: 52 | J32: 52 | K32: MERCK_TG | L32: 2.175 | M32: 2.08 | N32: 2.27 | O32: TC_ENG | Q32: 0.2 | R32: 0.22 | S32: TC_ENG | T32: 3 | U32: A
A33: 29 | B33: Poly(cyclohexyl acrylate) | C33: PCHA | D33: Acrylic | E33: *CC(C(=O)OC1CCCCC1)* | F33: PASS | H33: 19 | I33: 19 | J33: 19 | K33: MERCK_TG | T33: 1 | U33: C
A34: 30 | B34: Poly(cyclohexyl methacrylate) | C34: PCHMA | D34: Methacrylic | E34: *CC(C)(C(=O)OC1CCCCC1)* | F34: PASS | H34: 92 | I34: 92 | J34: 92 | K34: MERCK_TG | T34: 1 | U34: C
A35: 31 | B35: Poly(2,6-dichlorostyrene) | C35: P2,6Cl2S | D35: Styrenic | E35: *CC(c1c(Cl)cccc1Cl)* | F35: PASS | H35: 167 | I35: 167 | J35: 167 | K35: MERCK_TG | T35: 1 | U35: C
A36: 32 | B36: Poly(dimethylaminoethyl methacrylate) | C36: PDMAEMA | D36: Methacrylic | E36: *CC(C)(C(=O)OCCN(C)C)* | F36: PASS | H36: 19 | I36: 19 | J36: 19 | K36: MERCK_TG | T36: 1 | U36: C
A37: 33 | B37: Poly(diethylaminoethyl methacrylate) | C37: PDEAEMA | D37: Methacrylic | E37: *CC(C)(C(=O)OCCN(CC)CC)* | F37: PASS | H37: 20 | I37: 20 | J37: 20 | K37: MERCK_TG | T37: 1 | U37: C
A38: 34 | B38: Poly(2,6-dimethyl-1,4-phenylene oxide) | C38: PPO | D38: Aromatic polyether | E38: *Oc1c(C)cc(C)cc1* | F38: PASS | H38: 167 | I38: 167 | J38: 167 | K38: MERCK_TG | T38: 1 | U38: C
A39: 35 | B39: Poly(2,4-dimethylstyrene) | C39: P2,4DMS | D39: Styrenic | E39: *CC(c1c(C)cc(C)cc1)* | F39: PASS | H39: 112 | I39: 112 | J39: 112 | K39: MERCK_TG | T39: 1 | U39: C
A40: 36 | B40: Poly(2,5-dimethylstyrene) | C40: P2,5DMS | D40: Styrenic | E40: *CC(c1c(C)ccc(C)c1)* | F40: PASS | H40: 143 | I40: 143 | J40: 143 | K40: MERCK_TG | T40: 1 | U40: C
A41: 37 | B41: Poly(3,5-dimethylstyrene) | C41: P3,5DMS | D41: Styrenic | E41: *CC(c1cc(C)cc(C)c1)* | F41: PASS | H41: 104 | I41: 104 | J41: 104 | K41: MERCK_TG | T41: 1 | U41: C
A42: 38 | B42: Poly(ethyl acrylate) | C42: PEA | D42: Acrylic | E42: *CC(C(=O)OCC)* | F42: PASS | G42: High | H42: -23.2 | I42: -23.2 | J42: -23.2 | K42: POLYACRYLATE | L42: 1.12 | M42: 1.12 | N42: 1.12 | O42: POLYACRYLATE | T42: 2 | U42: B
...

Sheet HighQuality_Panel
A1: High-Quality External Validation Panel — paste AI predictions and compare to literature
A4: Polymer | B4: Acronym | C4: Repeat_SMILES | D4: Tire_Relevance | E4: Lit_Tg_C | F4: Lit_Tg_Min | G4: Lit_Tg_Max | H4: Tg_Source | I4: Lit_Density | J4: Density_Min | K4: Density_Max | L4: Density_Source | M4: Lit_Tc | N4: Tc_Min | O4: Tc_Max | P4: Tc_Source | Q4: AI_Tg | R4: AI_Density | S4: AI_FFV | T4: AI_Tc | U4: AI_Rg | V4: AbsErr_Tg | W4: AbsErr_Density | X4: AbsErr_Tc | Y4: Tg_In_Range | Z4: Density_In_Range | AA4: Tc_In_Range | AB4: Core_Available | AC4: Tier | AD4: Notes | AE4: FFV_warning | AF4: Rg_warning
A5: Poly(dimethylsiloxane) | B5: PDMS | C5: *O[Si](C)(C)* | E5: -127 | F5: -127 | G5: -127 | H5: MERCK_TG | Q5: 84.9131 | R5: 1.0456 | S5: 0.376 | T5: 0.2005 | U5: 18.0005 | V5: 211.9131 | W5: =IF(OR(R5="",I5=""),"",ABS(R5-I5)) | X5: =IF(OR(T5="",M5=""),"",ABS(T5-M5)) | Y5: FALSE | Z5: =IF(R5="","",IF(AND(R5>=J5,R5<=K5),"PASS","FAIL")) | AA5: =IF(T5="","",IF(AND(T5>=N5,T5<=O5),"PASS","FAIL")) | AB5: 1 | AC5: C | AE5: Compare only if FFV definition/protocol is matched. | AF5: Compare only if MW/chain length/state/solvent are matched.
A6: Polyacrylamide | B6: PAM | C6: *CC(C(=O)N)* | E6: 165 | F6: 165 | G6: 165 | H6: MERCK_TG | M6: 0.38 | N6: 0.38 | O6: 0.38 | P6: TC_REVIEW | Q6: 89.3807 | R6: 1.2478 | S6: 0.2504 | T6: 0.1849 | U6: 17.8009 | V6: 75.6193 | W6: =IF(OR(R6="",I6=""),"",ABS(R6-I6)) | X6: 0.1951 | Y6: FALSE | Z6: =IF(R6="","",IF(AND(R6>=J6,R6<=K6),"PASS","FAIL")) | AA6: FALSE | AB6: 2 | AC6: B | AE6: Compare only if FFV definition/protocol is matched. | AF6: Compare only if MW/chain length/state/solvent are matched.
A7: Poly(acrylic acid) | B7: PAA | C7: *CC(C(=O)O)* | E7: 105 | F7: 105 | G7: 105 | H7: MERCK_TG | M7: 0.37 | N7: 0.37 | O7: 0.37 | P7: TC_REVIEW | Q7: 88.7233 | R7: 1.1974 | S7: 0.2606 | T7: 0.1965 | U7: 18.4441 | V7: 16.2767 | W7: =IF(OR(R7="",I7=""),"",ABS(R7-I7)) | X7: 0.1735 | Y7: FALSE | Z7: =IF(R7="","",IF(AND(R7>=J7,R7<=K7),"PASS","FAIL")) | AA7: FALSE | AB7: 2 | AC7: B | AE7: Compare only if FFV definition/protocol is matched. | AF7: Compare only if MW/chain length/state/solvent are matched.
A8: Bisphenol-A polycarbonate | B8: BPA-PC | C8: *Oc1ccc(C(C)(C)c2ccc(OC(=O)O*)cc2)cc1 | E8: 145 | F8: 145 | G8: 145 | H8: PLASTICS_BOOK | I8: 1.2 | J8: 1.2 | K8: 1.2 | L8: PLASTICS_BOOK | N8: 0.18 | O8: 0.21 | P8: TC_ENG | Q8: 72.4188 | R8: 1.108 | S8: 0.3432 | T8: 0.2233 | U8: 20.0117 | V8: 72.5812 | W8: 0.092 | X8: =IF(OR(T8="",M8=""),"",ABS(T8-M8)) | Y8: FALSE | Z8: FALSE | AA8: FALSE | AB8: 3 | AC8: A | AE8: Compare only if FFV definition/protocol is matched. | AF8: Compare only if MW/chain length/state/solvent are matched.
A9: Poly(n-butyl acrylate) | B9: PnBA | C9: *CC(C(=O)OCCCC)* | D9: High | E9: -55.2 | F9: -55.2 | G9: -55.2 | H9: POLYACRYLATE | I9: 1.04 | J9: 1.04 | K9: 1.04 | L9: POLYACRYLATE | Q9: -25.6645 | R9: 0.9434 | S9: 0.374 | T9: 0.2291 | U9: 13.1101 | V9: 29.5355 | W9: 0.0966 | X9: =IF(OR(T9="",M9=""),"",ABS(T9-M9)) | Y9: FALSE | Z9: FALSE | AA9: =IF(T9="","",IF(AND(T9>=N9,T9<=O9),"PASS","FAIL")) | AB9: 2 | AC9: B | AE9: Compare only if FFV definition/protocol is matched. | AF9: Compare only if MW/chain length/state/solvent are matched.
A10: Poly(chlorotrifluoroethylene) | B10: PCTFE | C10: *C(F)(F)C(F)(Cl)* | E10: 52 | F10: 52 | G10: 52 | H10: MERCK_TG | I10: 2.175 | J10: 2.08 | K10: 2.27 | L10: TC_ENG | N10: 0.2 | O10: 0.22 | P10: TC_ENG | Q10: 13.1597 | R10: 1.5466 | S10: 0.3364 | T10: 0.1248 | U10: 20.6789 | V10: 38.8403 | W10: 0.6284 | X10: =IF(OR(T10="",M10=""),"",ABS(T10-M10)) | Y10: FALSE | Z10: FALSE | AA10: FALSE | AB10: 3 | AC10: A | AE10: Compare only if FFV definition/protocol is matched. | AF10: Compare only if MW/chain length/state/solvent are matched.
A11: Poly(ethyl acrylate) | B11: PEA | C11: *CC(C(=O)OCC)* | D11: High | E11: -23.2 | F11: -23.2 | G11: -23.2 | H11: POLYACRYLATE | I11: 1.12 | J11: 1.12 | K11: 1.12 | L11: POLYACRYLATE | Q11: 20.9601 | R11: 0.9863 | S11: 0.3597 | T11: 0.2246 | U11: 14.7455 | V11: 44.1601 | W11: 0.1337 | X11: =IF(OR(T11="",M11=""),"",ABS(T11-M11)) | Y11: FALSE | Z11: FALSE | AA11: =IF(T11="","",IF(AND(T11>=N11,T11<=O11),"PASS","FAIL")) | AB11: 2 | AC11: B | AE11: Compare only if FFV definition/protocol is matched. | AF11: Compare only if MW/chain length/state/solvent are matched.
A12: LDPE reference | B12: LDPE | C12: *CC* | D12: High | E12: -120 | F12: -120 | G12: -120 | H12: PLASTICS_BOOK | I12: 0.9225 | J12: 0.92 | K12: 0.925 | L12: PLASTICS_BOOK | M12: 0.34 | N12: 0.34 | O12: 0.34 | P12: TC_ENG | Q12: -5.8661 | R12: 0.8207 | S12: 0.4074 | T12: 0.3254 | U12: 25.1256 | V12: 114.1339 | W12: 0.1018 | X12: 0.0146 | Y12: FALSE | Z12: FALSE | AA12: FALSE | AB12: 3 | AC12: A | AD12: Same repeat SMILES as HDPE/MDPE; morphology/branching is not encoded by a simple repeat unit. | AE12: Compare only if FFV definition/protocol is matched. | AF12: Compare only if MW/chain length/state/solvent are matched.
A13: HDPE reference | B13: HDPE | C13: *CC* | D13: High | E13: -120 | F13: -120 | G13: -120 | H13: PLASTICS_BOOK | I13: 0.96 | J13: 0.955 | K13: 0.965 | L13: PLASTICS_BOOK | M13: 0.48 | N13: 0.46 | O13: 0.5 | P13: TC_ENG | Q13: -5.8661 | R13: 0.8207 | S13: 0.4074 | T13: 0.3254 | U13: 25.1256 | V13: 114.1339 | W13: 0.1393 | X13: 0.1546 | Y13: FALSE | Z13: FALSE | AA13: FALSE | AB13: 3 | AC13: A | AD13: Same repeat SMILES as LDPE; model cannot infer crystallinity/branching from *CC* alone. | AE13: Compare only if FFV definition/protocol is matched. | AF13: Compare only if MW/chain length/state/solvent are matched.
A14: Poly(ethylene terephthalate) | B14: PET | C14: *OCCOC(=O)c1ccc(C(=O)*)cc1 | E14: 80 | F14: 80 | G14: 80 | H14: PLASTICS_BOOK | I14: 1.338 | J14: 1.336 | K14: 1.34 | L14: PLASTICS_BOOK | N14: 0.14 | O14: 0.15 | P14: TC_ENG | Q14: 61.6787 | R14: 1.1593 | S14: 0.3345 | T14: 0.2167 | U14: 18.9819 | V14: 18.3213 | W14: 0.1787 | X14: =IF(OR(T14="",M14=""),"",ABS(T14-M14)) | Y14: FALSE | Z14: FALSE | AA14: FALSE | AB14: 3 | AC14: A | AD14: Density/Tc depend on crystallinity/orientation; value is a grade/reference range. | AE14: Compare only if FFV definition/protocol is matched. | AF14: Compare only if MW/chain length/state/solvent are matched.
A15: Poly(2-ethylhexyl acrylate) | B15: PEHA | C15: *CC(C(=O)OCC(CC)CCCC)* | D15: High | E15: -85.2 | F15: -85.2 | G15: -85.2 | H15: POLYACRYLATE | I15: 0.74 | J15: 0.74 | K15: 0.74 | L15: POLYACRYLATE | Q15: 13.431 | R15: 0.8968 | S15: 0.3846 | T15: 0.2334 | U15: 11.51 | V15: 98.631 | W15: 0.1568 | X15: =IF(OR(T15="",M15=""),"",ABS(T15-M15)) | Y15: FALSE | Z15: FALSE | AA15: =IF(T15="","",IF(AND(T15>=N15,T15<=O15),"PASS","FAIL")) | AB15: 2 | AC15: B | AE15: Compare only if FFV definition/protocol is matched. | AF15: Compare only if MW/chain length/state/solvent are matched.
A16: Polyisobutylene | B16: PIB | C16: *CC(C)(C)* | D16: High | E16: -73 | F16: -73 | G16: -73 | H16: MERCK_TG | Q16: 49.4963 | R16: 0.808 | S16: 0.3817 | T16: 0.2044 | U16: 16.3466 | V16: 122.4963 | W16: =IF(OR(R16="",I16=""),"",ABS(R16-I16)) | X16: =IF(OR(T16="",M16=""),"",ABS(T16-M16)) | Y16: FALSE | Z16: =IF(R16="","",IF(AND(R16>=J16,R16<=K16),"PASS","FAIL")) | AA16: =IF(T16="","",IF(AND(T16>=N16,T16<=O16),"PASS","FAIL")) | AB16: 1 | AC16: C | AD16: Backbone proxy for butyl rubber major component; IIR itself is a copolymer with small isoprene fraction. | AE16: Compare only if FFV definition/protocol is matched. | AF16: Compare only if MW/chain length/state/solvent are matched.
A17: cis-1,4-Polyisoprene / NR backbone | B17: PI/NR | C17: *CC(C)=CC* | D17: High | E17: -58.15 | F17: -58.15 | G17: -58.15 | H17: RUBBER_PALS | I17: 0.917 | J17: 0.91 | K17: 0.917 | L17: SBR_NR_DENS | M17: 0.14 | N17: 0.134 | O17: 0.145 | P17: RUBBER_TC | Q17: 10.9283 | R17: 0.7934 | S17: 0.4028 | T17: 0.2371 | U17: 14.6976 | V17: 69.0783 | W17: 0.1236 | X17: 0.0971 | Y17: FALSE | Z17: FALSE | AA17: FALSE | AB17: 3 | AC17: A | AD17: Tg from cured high-cis PI; density includes high-cis PI/NR references; Tc untreated PI. | AE17: Compare only if FFV definition/protocol is matched. | AF17: Compare only if MW/chain length/state/solvent are matched.
A18: Poly(methyl acrylate) | B18: PMA | C18: *CC(C(=O)OC)* | D18: High | E18: 8.9 | F18: 8.9 | G18: 8.9 | H18: POLYACRYLATE | I18: 1.22 | J18: 1.22 | K18: 1.22 | L18: POLYACRYLATE | Q18: 51.9447 | R18: 1.0327 | S18: 0.3321 | T18: 0.2163 | U18: 16.8598 | V18: 43.0447 | W18: 0.1873 | X18: =IF(OR(T18="",M18=""),"",ABS(T18-M18)) | Y18: FALSE | Z18: FALSE | AA18: =IF(T18="","",IF(AND(T18>=N18,T18<=O18),"PASS","FAIL")) | AB18: 2 | AC18: B | AE18: Compare only if FFV definition/protocol is matched. | AF18: Compare only if MW/chain length/state/solvent are matched.
A19: Atactic PMMA | B19: a-PMMA | C19: *CC(C)(C(=O)OC)* | E19: 105 | F19: 105 | G19: 105 | H19: MERCK_TG | I19: 1.19 | J19: 1.17 | K19: 1.2 | L19: PLASTICS_BOOK | M19: 0.2 | N19: 0.17 | O19: 0.25 | P19: TC_REVIEW | Q19: 74.2812 | R19: 0.9118 | S19: 0.344 | T19: 0.1637 | U19: 14.5456 | V19: 30.7188 | W19: 0.2782 | X19: 0.0363 | Y19: FALSE | Z19: FALSE | AA19: FALSE | AB19: 3 | AC19: A | AE19: Compare only if FFV definition/protocol is matched. | AF19: Compare only if MW/chain length/state/solvent are matched.
A20: Poly(4-methyl-1-pentene) | B20: P4MP | C20: *CC(CC(C)C)* | D20: High | E20: 25 | F20: 25 | G20: 25 | H20: PLASTICS_BOOK | I20: 0.83 | J20: 0.83 | K20: 0.83 | L20: PLASTICS_BOOK | Q20: 30.3138 | R20: 0.7594 | S20: 0.4017 | T20: 0.2059 | U20: 11.2994 | V20: 5.3138 | W20: 0.0706 | X20: =IF(OR(T20="",M20=""),"",ABS(T20-M20)) | Y20: FALSE | Z20: FALSE | AA20: =IF(T20="","",IF(AND(T20>=N20,T20<=O20),"PASS","FAIL")) | AB20: 2 | AC20: B | AE20: Compare only if FFV definition/protocol is matched. | AF20: Compare only if MW/chain length/state/solvent are matched.
A21: Nylon 6 / Polyamide 6 | B21: PA6 | C21: *NCCCCCC(=O)* | E21: 50 | F21: 50 | G21: 50 | H21: PLASTICS_BOOK | I21: 1.135 | J21: 1.12 | K21: 1.15 | L21: PLASTICS_BOOK | N21: 0.2 | O21: 0.3 | P21: TC_ENG | Q21: -1.8591 | R21: 0.9796 | S21: 0.3328 | T21: 0.2682 | U21: 15.5233 | V21: 51.8591 | W21: 0.1554 | X21: =IF(OR(T21="",M21=""),"",ABS(T21-M21)) | Y21: FALSE | Z21: FALSE | AA21: TRUE | AB21: 3 | AC21: A | AE21: Compare only if FFV definition/protocol is matched. | AF21: Compare only if MW/chain length/state/solvent are matched.
A22: Nylon 6,6 / Polyamide 66 | B22: PA66 | C22: *NCCCCCCNC(=O)CCCC(=O)* | E22: 57 | F22: 57 | G22: 57 | H22: PLASTICS_BOOK | I22: 1.145 | J22: 1.13 | K22: 1.16 | L22: PLASTICS_BOOK | N22: 0.2 | O22: 0.3 | P22: TC_ENG | Q22: 33.0527 | R22: 1.0075 | S22: 0.3274 | T22: 0.2664 | U22: 18.7265 | V22: 23.9473 | W22: 0.1375 | X22: =IF(OR(T22="",M22=""),"",ABS(T22-M22)) | Y22: FALSE | Z22: FALSE | AA22: TRUE | AB22: 3 | AC22: A | AE22: Compare only if FFV definition/protocol is matched. | AF22: Compare only if MW/chain length/state/solvent are matched.
A23: Nylon 11 | B23: PA11 | C23: *NCCCCCCCCCCC(=O)* | E23: 42 | F23: 42 | G23: 42 | H23: MERCK_TG | N23: 0.34 | O23: 0.35 | P23: TC_ENG | Q23: -13.4918 | R23: 0.9084 | S23: 0.3609 | T23: 0.3438 | U23: 21.4125 | V23: 55.4918 | W23: =IF(OR(R23="",I23=""),"",ABS(R23-I23)) | X23: =IF(OR(T23="",M23=""),"",ABS(T23-M23)) | Y23: FALSE | Z23: =IF(R23="","",IF(AND(R23>=J23,R23<=K23),"PASS","FAIL")) | AA23: TRUE | AB23: 2 | AC23: B | AE23: Compare only if FFV definition/protocol is matched. | AF23: Compare only if MW/chain length/state/solvent are matched.
A24: Nylon 12 | B24: PA12 | C24: *NCCCCCCCCCCCC(=O)* | E24: 41 | F24: 41 | G24: 41 | H24: MERCK_TG | I24: 1.02 | J24: 1.02 | K24: 1.02 | L24: ENG_DENS | N24: 0.25 | O24: 0.35 | P24: TC_ENG | Q24: -7.8104 | R24: 0.8937 | S24: 0.3604 | T24: 0.336 | U24: 20.6451 | V24: 48.8104 | W24: 0.1263 | X24: =IF(OR(T24="",M24=""),"",ABS(T24-M24)) | Y24: FALSE | Z24: FALSE | AA24: TRUE | AB24: 3 | AC24: A | AE24: Compare only if FFV definition/protocol is matched. | AF24: Compare only if MW/chain length/state/solvent are matched.
A25: Atactic polypropylene | B25: a-PP | C25: *CC(C)* | D25: High | E25: -13 | F25: -13 | G25: -13 | H25: MERCK_TG | I25: 0.905 | J25: 0.9 | K25: 0.91 | L25: PLASTICS_BOOK | N25: 0.12 | O25: 0.2 | P25: TC_ENG | Q25: 12.6697 | R25: 0.7961 | S25: 0.3962 | T25: 0.2379 | U25: 15.6557 | V25: 25.6697 | W25: 0.1089 | X25: =IF(OR(T25="",M25=""),"",ABS(T25-M25)) | Y25: FALSE | Z25: FALSE | AA25: FALSE | AB25: 3 | AC25: A | AD25: Tacticity is not explicit in plain 2D repeat SMILES. | AE25: Compare only if FFV definition/protocol is matched. | AF25: Compare only if MW/chain length/state/solvent are matched.
A26: Isotactic polypropylene | B26: i-PP | C26: *CC(C)* | D26: High | E26: -8 | F26: -8 | G26: -8 | H26: MERCK_TG | I26: 0.905 | J26: 0.9 | K26: 0.91 | L26: PLASTICS_BOOK | N26: 0.12 | O26: 0.2 | P26: TC_ENG | Q26: 12.6697 | R26: 0.7961 | S26: 0.3962 | T26: 0.2379 | U26: 15.6557 | V26: 20.6697 | W26: 0.1089 | X26: =IF(OR(T26="",M26=""),"",ABS(T26-M26)) | Y26: FALSE | Z26: FALSE | AA26: FALSE | AB26: 3 | AC26: A | AD26: Tacticity is not explicit in plain 2D repeat SMILES. | AE26: Compare only if FFV definition/protocol is matched. | AF26: Compare only if MW/chain length/state/solvent are matched.
A27: Polytetrafluoroethylene | B27: PTFE | C27: *C(F)(F)C(F)(F)* | E27: -73 | F27: -73 | G27: -73 | H27: PLASTICS_BOOK | I27: 2.2 | J27: 2.14 | K27: 2.2 | L27: PLASTICS_BOOK | N27: 0.24 | O27: 0.27 | P27: TC_ENG | Q27: 8.3746 | R27: 1.4671 | S27: 0.3143 | T27: 0.1436 | U27: 20.6833 | V27: 81.3746 | W27: 0.7329 | X27: =IF(OR(T27="",M27=""),"",ABS(T27-M27)) | Y27: FALSE | Z27: FALSE | AA27: FALSE | AB27: 3 | AC27: A | AD27: PTFE has multiple relaxations/transitions; Tg assignment is source-dependent. Merck lists 117 C while the cited engineering text lists -73 C. | AE27: Compare only if FFV definition/protocol is matched. | AF27: Compare only if MW/chain length/state/solvent are matched.
A28: Poly(butylene terephthalate) | B28: PBT | C28: *OCCCCOC(=O)c1ccc(C(=O)*)cc1 | E28: 17 | F28: 17 | G28: 17 | H28: MERCK_TG | I28: 1.31 | J28: 1.31 | K28: 1.31 | L28: ENG_DENS | N28: 0.18 | O28: 0.29 | P28: TC_ENG | Q28: 40.9775 | R28: 1.1236 | S28: 0.3397 | T28: 0.2285 | U28: 19.7021 | V28: 23.9775 | W28: 0.1864 | X28: =IF(OR(T28="",M28=""),"",ABS(T28-M28)) | Y28: FALSE | Z28: FALSE | AA28: TRUE | AB28: 3 | AC28: A | AE28: Compare only if FFV definition/protocol is matched. | AF28: Compare only if MW/chain length/state/solvent are matched.
A29: Poly(vinyl alcohol) | B29: PVA | C29: *CC(O)* | D29: High | E29: 85 | F29: 85 | G29: 85 | H29: MERCK_TG | M29: 0.31 | N29: 0.31 | O29: 0.31 | P29: TC_REVIEW | Q29: 41.9842 | R29: 1.0838 | S29: 0.3222 | T29: 0.3717 | U29: 21.5842 | V29: 43.0158 | W29: =IF(OR(R29="",I29=""),"",ABS(R29-I29)) | X29: 0.0617 | Y29: FALSE | Z29: =IF(R29="","",IF(AND(R29>=J29,R29<=K29),"PASS","FAIL")) | AA29: FALSE | AB29: 2 | AC29: B | AE29: Compare only if FFV definition/protocol is matched. | AF29: Compare only if MW/chain length/state/solvent are matched.
A30: Poly(vinyl chloride) | B30: PVC | C30: *CC(Cl)* | D30: High | E30: 80 | F30: 80 | G30: 80 | H30: PLASTICS_BOOK | I30: 1.41 | J30: 1.41 | K30: 1.41 | L30: PLASTICS_BOOK | N30: 0.15 | O30: 0.21 | P30: TC_ENG | Q30: 21.7729 | R30: 1.2446 | S30: 0.3816 | T30: 0.1644 | U30: 20.5076 | V30: 58.2271 | W30: 0.1654 | X30: =IF(OR(T30="",M30=""),"",ABS(T30-M30)) | Y30: FALSE | Z30: FALSE | AA30: TRUE | AB30: 3 | AC30: A | AE30: Compare only if FFV definition/protocol is matched. | AF30: Compare only if MW/chain length/state/solvent are matched.
A31: Poly(vinylidene chloride) | B31: PVDC | C31: *CC(Cl)(Cl)* | E31: -18 | F31: -18 | G31: -18 | H31: PLASTICS_BOOK | I31: 1.75 | J31: 1.75 | K31: 1.75 | L31: PLASTICS_BOOK | Q31: 40.6771 | R31: 1.4171 | S31: 0.3747 | T31: 0.112 | U31: 19.9037 | V31: 58.6771 | W31: 0.3329 | X31: =IF(OR(T31="",M31=""),"",ABS(T31-M31)) | Y31: FALSE | Z31: FALSE | AA31: =IF(T31="","",IF(AND(T31>=N31,T31<=O31),"PASS","FAIL")) | AB31: 2 | AC31: B | AE31: Compare only if FFV definition/protocol is matched. | AF31: Compare only if MW/chain length/state/solvent are matched.
A32: Poly(vinylidene fluoride) | B32: PVDF | C32: *CC(F)(F)* | E32: -40 | F32: -40 | G32: -40 | H32: MERCK_TG | I32: 1.78 | J32: 1.76 | K32: 1.78 | L32: TC_ENG | N32: 0.1 | O32: 0.13 | P32: TC_ENG | Q32: 1.7133 | R32: 1.2645 | S32: 0.3344 | T32: 0.1877 | U32: 21.3563 | V32: 41.7133 | W32: 0.5155 | X32: =IF(OR(T32="",M32=""),"",ABS(T32-M32)) | Y32: FALSE | Z32: FALSE | AA32: FALSE | AB32: 3 | AC32: A | AE32: Compare only if FFV definition/protocol is matched. | AF32: Compare only if MW/chain length/state/solvent are matched.
A33: High-cis 1,4-polybutadiene / BR | B33: PB/BR | C33: *CC=CC* | D33: High | E33: -107 | F33: -107 | G33: -107 | H33: RUBBER_PALS | I33: 0.93 | J33: 0.93 | K33: 0.93 | L33: RUBBER_PALS | M33: 0.174 | N33: 0.174 | O33: 0.19 | P33: RUBBER_TC | Q33: -34.7298 | R33: 0.8331 | S33: 0.416 | T33: 0.2731 | U33: 19.5628 | V33: 72.2702 | W33: 0.0969 | X33: 0.0991 | Y33: FALSE | Z33: FALSE | AA33: FALSE | AB33: 3 | AC33: A | AD33: Tg/density from cured high-cis PB; Tc from untreated PB. Strong tire relevance. | AE33: Compare only if FFV definition/protocol is matched. | AF33: Compare only if MW/chain length/state/solvent are matched.
A34: Polyoxymethylene | B34: POM | C34: *CO* | E34: -85 | F34: -85 | G34: -85 | H34: PLASTICS_BOOK | I34: 1.41 | J34: 1.41 | K34: 1.42 | L34: PLASTICS_BOOK | N34: 0.23 | O34: 0.3 | P34: TC_ENG | Q34: 26.6784 | R34: 1.201 | S34: 0.3583 | T34: 0.2546 | U34: 21.3496 | V34: 111.6784 | W34: 0.209 | X34: =IF(OR(T34="",M34=""),"",ABS(T34-M34)) | Y34: FALSE | Z34: FALSE | AA34: TRUE | AB34: 3 | AC34: A | AE34: Compare only if FFV definition/protocol is matched. | AF34: Compare only if MW/chain length/state/solvent are matched.
A35: Polylactic acid | B35: PLA | C35: *OC(C)C(=O)* | E35: 61.85 | F35: 61.85 | G35: 61.85 | H35: MERCK_TG | N35: 0.064 | O35: 0.09 | P35: TC_REVIEW | Q35: 103.2977 | R35: 1.0843 | S35: 0.3532 | T35: 0.1865 | U35: 18.4816 | V35: 41.4477 | W35: =IF(OR(R35="",I35=""),"",ABS(R35-I35)) | X35: =IF(OR(T35="",M35=""),"",ABS(T35-M35)) | Y35: FALSE | Z35: =IF(R35="","",IF(AND(R35>=J35,R35<=K35),"PASS","FAIL")) | AA35: FALSE | AB35: 2 | AC35: B | AD35: Tc literature range in 2024 review. | AE35: Compare only if FFV definition/protocol is matched. | AF35: Compare only if MW/chain length/state/solvent are matched.

Sheet FFV_Rg_Conditioned
A1: FFV / PALS / Rg Conditioned Measurements — DO NOT compare blindly to AI outputs
A4: Type | B4: Polymer | C4: Repeat_SMILES | D4: Value | E4: Unit | F4: Definition_or_Method | G4: Tg_K_if_relevant | H4: Mw_g_mol | I4: Degree_of_Polymerization | J4: Condition | K4: Extra | L4: Directly_Comparable_to_AI? | M4: Source_ID | N4: Interpretation
A5: FFV | B5: PDMS | C5: *O[Si](C)(C)* | D5: 0.086 | E5: fraction | F5: Fractional excess free volume at Tg (model from neutron-derived expansion data) | G5: 150 | L5: NO | M5: FFV_PS | N5: Different definition/condition: use as mechanistic reference, not a universal target.
A6: FFV | B6: PDMS | C6: *O[Si](C)(C)* | D6: 0.071 | E6: fraction | F6: WLF literature fractional excess free volume at Tg | G6: 150 | L6: NO | M6: FFV_PS | N6: Different definition/condition: use as mechanistic reference, not a universal target.
A7: FFV | B7: PB | C7: *CC=CC* | D7: 0.012 | E7: fraction | F7: Fractional excess free volume at Tg | G7: 172 | L7: NO | M7: FFV_PS | N7: Different definition/condition: use as mechanistic reference, not a universal target.
A8: FFV | B8: PB | C8: *CC=CC* | D8: 0.038 | E8: fraction | F8: WLF literature fractional excess free volume at Tg | G8: 172 | L8: NO | M8: FFV_PS | N8: Different definition/condition: use as mechanistic reference, not a universal target.
A9: FFV | B9: PIB | C9: *CC(C)(C)* | D9: 0.117 | E9: fraction | F9: Fractional excess free volume at Tg | G9: 205 | L9: NO | M9: FFV_PS | N9: Different definition/condition: use as mechanistic reference, not a universal target.
A10: FFV | B10: PIB | C10: *CC(C)(C)* | D10: 0.026 | E10: fraction | F10: WLF literature fractional excess free volume at Tg | G10: 205 | L10: NO | M10: FFV_PS | N10: Different definition/condition: use as mechanistic reference, not a universal target.
A11: FFV | B11: PVAc | C11: *CC(OC(=O)C)* | D11: 0.086 | E11: fraction | F11: Fractional excess free volume at Tg | G11: 305 | L11: NO | M11: FFV_PS | N11: Different definition/condition: use as mechanistic reference, not a universal target.
A12: FFV | B12: PVAc | C12: *CC(OC(=O)C)* | D12: 0.028 | E12: fraction | F12: WLF literature fractional excess free volume at Tg | G12: 305 | L12: NO | M12: FFV_PS | N12: Different definition/condition: use as mechanistic reference, not a universal target.
A13: FFV | B13: PMMA | C13: *CC(C)(C(=O)OC)* | D13: 0.055 | E13: fraction | F13: Fractional excess free volume at Tg | G13: 381 | L13: NO | M13: FFV_PS | N13: Different definition/condition: use as mechanistic reference, not a universal target.
A14: FFV | B14: PMMA | C14: *CC(C)(C(=O)OC)* | D14: 0.013 | E14: fraction | F14: WLF literature fractional excess free volume at Tg | G14: 381 | L14: NO | M14: FFV_PS | N14: Different definition/condition: use as mechanistic reference, not a universal target.
A15: FFV | B15: PS | C15: *CC(c1ccccc1)* | D15: 0.015 | E15: fraction | F15: Fractional excess free volume at Tg | G15: 373 | L15: NO | M15: FFV_PS | N15: Different definition/condition: use as mechanistic reference, not a universal target.
A16: FFV | B16: PS | C16: *CC(c1ccccc1)* | D16: 0.027 | E16: fraction | F16: WLF literature fractional excess free volume at Tg | G16: 373 | L16: NO | M16: FFV_PS | N16: Different definition/condition: use as mechanistic reference, not a universal target.
A17: PALS | B17: LDPE | C17: *CC* | D17: 0.33 | E17: nm | F17: PALS free-volume-hole radius R3; intensity 21.1% | L17: NO | M17: PALS_REVIEW | N17: Different definition/condition: use as mechanistic reference, not a universal target.
A18: PALS | B18: HDPE | C18: *CC* | D18: 0.32 | E18: nm | F18: PALS free-volume-hole radius R3; intensity 19.7% | L18: NO | M18: PALS_REVIEW | N18: Different definition/condition: use as mechanistic reference, not a universal target.
A19: PALS | B19: PA6 | C19: *NCCCCCC(=O)* | D19: 0.24 | E19: nm | F19: PALS free-volume-hole radius R3; intensity 24.5% | L19: NO | M19: PALS_REVIEW | N19: Different definition/condition: use as mechanistic reference, not a universal target.
A20: PALS | B20: PMMA | C20: *CC(C)(C(=O)OC)* | D20: 0.28 | E20: nm | F20: PALS free-volume-hole radius R3; intensity 23.6% | L20: NO | M20: PALS_REVIEW | N20: Different definition/condition: use as mechanistic reference, not a universal target.
A21: PALS | B21: PET | C21: *OCCOC(=O)c1ccc(C(=O)*)cc1 | D21: 0.25 | E21: nm | F21: PALS free-volume-hole radius R3; intensity 20.4% | L21: NO | M21: PALS_REVIEW | N21: Different definition/condition: use as mechanistic reference, not a universal target.
A22: PALS | B22: cis-PB | C22: *CC=CC* | D22: 0.34 | E22: nm | F22: PALS free-volume-hole radius R3; intensity 39.45% | L22: NO | M22: PALS_REVIEW | N22: Different definition/condition: use as mechanistic reference, not a universal target.
A23: PALS | B23: SBR | C23: copolymer | D23: 0.33 | E23: nm | F23: PALS free-volume-hole radius R3; intensity 34.2% | L23: NO | M23: PALS_REVIEW | N23: Different definition/condition: use as mechanistic reference, not a universal target.
A24: PALS | B24: PDMS | C24: *O[Si](C)(C)* | D24: 0.39 | E24: nm | F24: PALS free-volume-hole radius R3; intensity 30.3% | L24: NO | M24: PALS_REVIEW | N24: Different definition/condition: use as mechanistic reference, not a universal target.
A25: PALS | B25: PTFE-small | C25: *C(F)(F)C(F)(F)* | D25: 0.19 | E25: nm | F25: PALS free-volume-hole radius R3; intensity 9.6% | L25: NO | M25: PALS_REVIEW | N25: Different definition/condition: use as mechanistic reference, not a universal target.
A26: PALS | B26: PTFE-large | C26: *C(F)(F)C(F)(F)* | D26: 0.43 | E26: nm | F26: PALS larger free-volume-hole radius R4; intensity 13.8% | L26: NO | M26: PALS_REVIEW | N26: Different definition/condition: use as mechanistic reference, not a universal target.
A27: RG | B27: PS bulk | C27: *CC(c1ccccc1)* | D27: 90 | E27: A | F27: Low-angle neutron scattering bulk polymer | H27: 97200 | J27: bulk solid | L27: CONDITIONAL | M27: RG_PS | N27: Potentially usable only after matching the AI target protocol/chain length/state.
A28: RG | B28: PS solution 1 | C28: *CC(c1ccccc1)* | D28: 540 | E28: A | F28: Static light scattering; good solvent | H28: 1240000 | J28: benzene solution | L28: NO | M28: RG_SLS | N28: Different definition/condition: use as mechanistic reference, not a universal target.
A29: RG | B29: PS solution 2 | C29: *CC(c1ccccc1)* | D29: 1100 | E29: A | F29: Static light scattering; good solvent | H29: 4000000 | J29: benzene solution | L29: NO | M29: RG_SLS | N29: Different definition/condition: use as mechanistic reference, not a universal target.
A30: RG | B30: PI solution 1 | C30: *CC(C)=CC* | D30: 280 | E30: A | F30: Static light scattering; good solvent | H30: 310000 | J30: cyclohexane solution | L30: NO | M30: RG_SLS | N30: Different definition/condition: use as mechanistic reference, not a universal target.
A31: RG | B31: PI solution 2 | C31: *CC(C)=CC* | D31: 540 | E31: A | F31: Static light scattering; good solvent | H31: 940000 | J31: cyclohexane solution | L31: NO | M31: RG_SLS | N31: Different definition/condition: use as mechanistic reference, not a universal target.
A32: RG | B32: PB solution | C32: *CC=CC* | D32: 530 | E32: A | F32: Static light scattering; good solvent | H32: 960000 | J32: cyclohexane solution | L32: NO | M32: RG_SLS | N32: Different definition/condition: use as mechanistic reference, not a universal target.
A33: RG | B33: PEO/PEG 76-mer | C33: *OCC* | D33: 19.1 | E33: A | F33: 76-mer PEO model benchmarked to equal-size PEG neutron scattering | H33: 3400 | I33: 76 | J33: water / equal-size PEG experimental benchmark | L33: CONDITIONAL | M33: RG_PEO | N33: Potentially usable only after matching the AI target protocol/chain length/state.
A34: RG | B34: PB concentration 5.0 g/L | C34: *CC=CC* | D34: 143 | E34: A | F34: Apparent Rg from light scattering | H34: 270000 | J34: CHCl3, 5.0 g/L | L34: NO | M34: RG_PB_CONC | N34: Different definition/condition: use as mechanistic reference, not a universal target.
A35: RG | B35: PB concentration 2.9 g/L | C35: *CC=CC* | D35: 221 | E35: A | F35: Apparent Rg from light scattering | H35: 270000 | J35: CHCl3, 2.9 g/L | L35: NO | M35: RG_PB_CONC | N35: Different definition/condition: use as mechanistic reference, not a universal target.
A36: RG | B36: PB concentration 1.2 g/L | C36: *CC=CC* | D36: 374 | E36: A | F36: Apparent Rg from light scattering | H36: 270000 | J36: CHCl3, 1.2 g/L | L36: NO | M36: RG_PB_CONC | N36: Different definition/condition: use as mechanistic reference, not a universal target.

Sheet Industrial_Copolymers
A1: Industrial / Tire Copolymers & Blends — composition-sensitive references
A4: Acronym | B4: Material | C4: Use | D4: Composition | E4: SMILES guidance | F4: Composition/grade | G4: Tg_Min_C | H4: Tg_Max_C | I4: Density_Min | J4: Density_Max | K4: Tc_Min | L4: Tc_Max | M4: Source_IDs | N4: Notes
A5: SBR | B5: Styrene-butadiene rubber | C5: Tire tread / carcass | D5: Styrene + butadiene random copolymer | E5: No single unique repeat-unit SMILES | F5: 23.5 wt% styrene example | G5: -70 | H5: -50 | I5: 0.935 | J5: 0.94 | M5: SBR_PROP;SBR_NR_DENS | N5: Tg strongly composition/microstructure/crosslink dependent.
A6: SBR-vulc | B6: Vulcanized SBR | C6: Tire rubber | D6: 23.5 wt% styrene SBR; sulfur-crosslinked | E6: No single unique repeat-unit SMILES | F6: S = 1.04 to 8.28 phr | G6: -54 | H6: -37.1 | M6: SBR_TG | N6: DSC Tg increases with sulfur/crosslinking; exact values 219.17–236.10 K.
A7: NBR | B7: Nitrile-butadiene rubber | C7: Oil-resistant rubber / special tire uses | D7: Acrylonitrile + butadiene copolymer | E7: No single unique repeat-unit SMILES | F7: 39% AN example | I7: 0.99 | J7: 0.99 | K7: 0.157 | L7: 0.157 | M7: NBR_DENS;NBR_TC | N7: Tg varies strongly with acrylonitrile content.
A8: HNBR | B8: Hydrogenated NBR | C8: Seals / high-temperature elastomer | D8: Hydrogenated NBR copolymer | E8: No single unique repeat-unit SMILES | F8: 36 wt% ACN example | G8: -25.15 | H8: -25.15 | I8: 0.95 | J8: 0.95 | M8: HNBR_EPDM | N8: Experimental reference in source: Tg 248 K, density 0.95.
A9: EPDM | B9: Ethylene-propylene-diene rubber | C9: Sidewall / weather-resistant rubber | D9: Ethylene + propylene + ENB terpolymer | E9: No single unique repeat-unit SMILES | F9: 54/38/8 wt% E/P/ENB example | G9: -55.15 | H9: -55.15 | I9: 0.86 | J9: 0.86 | M9: HNBR_EPDM | N9: Experimental reference in source: Tg 218 K, density 0.86.
A10: IIR | B10: Butyl rubber | C10: Inner liner / air retention | D10: Isobutylene + small isoprene fraction | E10: PIB backbone is a useful proxy: *CC(C)(C)* | F10: 1.6% isoprene commercial IIR | I10: 0.92 | J10: 0.92 | M10: IIR | N10: Do not treat pure PIB SMILES as a full IIR composition.
A11: NR/SBR blend | B11: Natural rubber + SBR blend | C11: Tire compound | D11: Blend, not a single polymer | E11: Not representable by one repeat SMILES | F11: Source reports neat precursor densities | I11: 0.917 | J11: 0.935 | M11: SBR_NR_DENS | N11: NR density 0.917; SBR 0.935 g/cm3 at room temperature.
A12: ABS | B12: Acrylonitrile-butadiene-styrene | C12: Engineering plastic | D12: Terpolymer | E12: No single unique repeat-unit SMILES | F12: Grade-dependent | G12: 100 | H12: 100 | I12: 0.99 | J12: 1.1 | K12: 0.18 | L12: 0.32 | M12: PLASTICS_BOOK;TC_ENG | N12: Not a tire elastomer; useful OOD/industrial validation.
A13: SAN | B13: Styrene-acrylonitrile | C13: Engineering plastic | D13: Styrene + acrylonitrile copolymer | E13: No single unique repeat-unit SMILES | F13: Grade-dependent | G13: 100 | H13: 100 | I13: 1.08 | J13: 1.08 | K13: 0.12 | L13: 0.13 | M13: PLASTICS_BOOK;TC_ENG | N13: Composition-dependent.

Sheet Sources
A1: Source Register — URLs are plain text for traceability
A4: Source_ID | B4: Title | C4: Year | D4: Type | E4: URL | F4: Used_for | G4: Quality / comparability note
A5: ENG_DENS | B5: ScienceDirect Topics — Engineering plastics / polymer material property tables | D5: Elsevier reference aggregation | E5: https://www.sciencedirect.com/topics/engineering/polymer-material | F5: Selected density values for PBT, PA12 and engineering polymers | G5: Used where a direct table value was surfaced.
A6: FFV_PS | B6: The Relationship between Free Volume and Cooperative Rearrangement: From the Temperature-Dependent Neutron Total Scattering Experiment of Polystyrene | C6: 2021 | D6: Peer-reviewed experimental/model analysis | E6: https://pmc.ncbi.nlm.nih.gov/articles/PMC8470135/ | F6: Fractional excess free volume at Tg for PDMS, PB, PIB, PVAc, PMMA, PS | G6: Definition is fractional EXCESS free volume near Tg, not necessarily the same geometric FFV target used by the AI model.
A7: HNBR_EPDM | B7: Molecular simulations of gas transport in hydrogenated nitrile butadiene rubber and ethylene-propylene-diene rubber | C7: 2020 | D7: Peer-reviewed study with experimental references | E7: https://pmc.ncbi.nlm.nih.gov/articles/PMC9051154/ | F7: Experimental HNBR/EPDM density and Tg | G7: Table 1: HNBR exp rho 0.95, Tg 248 K; EPDM exp rho 0.86, Tg 218 K.
A8: IIR | B8: Influence of Alternating Multi-Layered Design on Damping Characteristics of Butyl Rubber Composites | C8: 2022 | D8: Peer-reviewed experiment | E8: https://www.mdpi.com/2073-4360/14/24/5484 | F8: Commercial IIR density | G8: BK1675N butyl rubber, 1.6% isoprene, density 0.92 g/cm3.
A9: MERCK_TG | B9: Thermal Transitions of Homopolymers: Glass Transition & Melting Point | D9: Technical literature compilation | E9: https://www.merckmillipore.com/ST/en/technical-documents/technical-article/materials-science-and-engineering/polymer-synthesis/thermal-transitions-of-homopolymers | F9: Large homopolymer Tg library | G9: Merck explicitly warns Tg varies with MW, tacticity, thermal history, purity and method.
A10: NBR_DENS | B10: Entanglements, Defects, and Inhomogeneities in Nitrile Butadiene Rubbers | C10: 2016 | D10: Peer-reviewed experiment | E10: https://pubs.acs.org/doi/10.1021/acs.macromol.6b01802 | F10: NBR/HNBR density and molecular weights | G10: 39% AN NBR density 0.99 g/cm3; HNBR same AN content density 0.95 g/cm3.
A11: NBR_TC | B11: Novel nitrile-butadiene rubber composites with enhanced thermal conductivity and high dielectric constant | C11: 2019 | D11: Peer-reviewed experiment | E11: https://www.sciencedirect.com/science/article/pii/S1359835X19301903 | F11: Pure NBR thermal conductivity | G11: Pure NBR matrix k = 0.157 W/mK in the cited study.
A12: PALS_REVIEW | B12: Positron Annihilation Lifetime Spectroscopy for Free-Volume Holes in Polymers | C12: 2023 | D12: Peer-reviewed review | E12: https://pmc.ncbi.nlm.nih.gov/articles/PMC10386335/ | F12: PALS hole radius / intensity for many polymers | G12: PALS hole size/intensity is not a direct FFV fraction.
A13: PLASTICS_BOOK | B13: Plastics: Microstructure and Engineering Applications, 4th ed. — Table 1.2 | C13: 2020 | D13: Elsevier textbook | E13: https://www.sciencedirect.com/book/monograph/9780081024997/plastics | F13: Density and Tg of major commodity/engineering polymers | G13: Density ranges reflect crystallinity/grade where applicable.
A14: POLYACRYLATE | B14: Polymer free-volume / density study including PS and polyacrylates | C14: 2021 | D14: Peer-reviewed experiment | E14: https://pmc.ncbi.nlm.nih.gov/articles/PMC8309325/ | F14: PMA/PEA/PBA/PEHA Tg and density series | G14: Useful homologous side-chain validation series.
A15: RG_PB_CONC | B15: Solvent-Dependent Light-Induced Structures in Gem-Dichlorocyclopropanated Polybutadiene Solutions | C15: 2018 | D15: Peer-reviewed light scattering | E15: https://pmc.ncbi.nlm.nih.gov/articles/PMC6122843/ | F15: PB Rg concentration dependence | G15: Same Mw PB gives very different apparent Rg with concentration; useful warning for direct AI comparison.
A16: RG_PEO | B16: A Coarse-Grained Model for Polyethylene Oxide and Polyethylene Glycol: Conformation and Hydrodynamics | C16: 2009 | D16: Peer-reviewed simulation benchmarked to neutron scattering | E16: https://pubs.acs.org/doi/10.1021/jp9058966 | F16: PEO/PEG 76-mer Rg | G16: Rg 19.1 +/-0.7 A in model, reported as excellent agreement with equal-sized PEG neutron scattering.
A17: RG_PS | B17: Measurement of molecular dimensions of polystyrene chains in the bulk polymer by low angle neutron diffraction | C17: 1973 | D17: Peer-reviewed experiment | E17: https://www.sciencedirect.com/science/article/pii/0014305773900591 | F17: Bulk PS Rg = 90 A at Ma=97,200 | G17: Rg is molecular-weight and state dependent.
A18: RG_SLS | B18: On the Number of Blobs per Entanglement in Semidilute and Good Solvent Solution: Melt Influence | C18: 1995 | D18: Peer-reviewed static light scattering | E18: https://pubs.acs.org/doi/10.1021/ma00108a020 | F18: PS/PI/PB Rg vs molecular weight | G18: Solution SLS values; not directly comparable to a fixed-chain MD Rg unless MW/condition are matched.
A19: RUBBER_PALS | B19: Shape and Temperature Expansion of Free Volume Holes in Some Cured Polybutadiene-Polyisoprene Rubber Blends | C19: 2021 | D19: Peer-reviewed experimental | E19: https://pmc.ncbi.nlm.nih.gov/articles/PMC7867040/ | F19: High-cis PB/PI density, Tg and PALS free-volume-hole information | G19: Samples are peroxide-cured high-cis rubbers; not identical to untreated neat chains.
A20: RUBBER_TC | B20: Thermal Conductivity of Polyisoprene and Polybutadiene from Molecular Dynamics Simulations and Transient Measurements | C20: 2020 | D20: Peer-reviewed experimental + simulation | E20: https://pmc.ncbi.nlm.nih.gov/articles/PMC7284750/ | F20: Untreated PI/PB thermal conductivity | G20: Transient hot-wire measurements; PI ~0.14 W/mK at 22 C.
A21: SBR_NR_DENS | B21: Thermal properties in cured natural rubber/styrene butadiene rubber blends | C21: 2008 | D21: Peer-reviewed experiment | E21: https://www.sciencedirect.com/science/article/pii/S0014305708000815 | F21: NR and SBR room-temperature density | G21: NR 0.917 g/cm3, SBR 0.935 g/cm3; Mn values also reported.
... A25: TC_REVIEW | B25: Thermal Conductivity of Polymers: A Simple Matter Where Complexity Matters | C25: 2024 | D25: Peer-reviewed review | E25: https://pmc.ncbi.nlm.nih.gov/articles/PMC11661673/ | F25: Experimental thermal conductivity and Tg for PLA, PS, PMMA, PVA, PAA, PAM | G25: PNIPAM thermal conductivity in that table is simulation; excluded from direct experimental Tc.
